{
    "output": "Unknown exception while setting up: Traceback (most recent call last):\n  File \"test_set_3.py\", line 457, in run_tests\n    lambda: imp.load_source('set_3_for_testing', '/tmp/set_3_for_testing.py'))()\n  File \"/tmp/set_3_for_testing.py\", line 2231\nSyntaxError: Non-ASCII character '\\xe2' in file /tmp/set_3_for_testing.py on line 2231, but no encoding declared; see http://python.org/dev/peps/pep-0263/ for details\n",
    "score": 0.0
}